Workbook

Sheet Event Calendar
A1: SERA 2026 — ANNUAL EVENT CALENDAR & BUDGET OVERVIEW
A2: Saudi Electricity Regulatory Authority (هيئة تنظيم الكهرباء) | All Events in Riyadh | Agency Commission: 15%
A4: # | B4: Event Name | C4: Arabic Name | D4: Date | E4: Qtr | F4: Category | G4: Est. Attendance | H4: Event Tier
A5: 1 | B5: Annual Meeting 2026 | C5: الاجتماع السنوي | D5: February 3 | E5: Q1 | F5: Corporate Conference | G5: 300 | H5: Major
A6: 2 | B6: Founding Day | C6: يوم التأسيس | D6: February 22 | E6: Q1 | F6: National Celebration | G6: 300 | H6: Light
A7: 3 | B7: Employee Appreciation Day | C7: يوم تقدير الموظف | D7: March 2 | E7: Q1 | F7: Recognition Gala | G7: 300 | H7: Major
A8: 4 | B8: International Women's Day | C8: اليوم العالمي للمرأة | D8: March 8 | E8: Q1 | F8: Awareness/Celebration | G8: 150 | H8: Medium
A9: 5 | B9: Saudi Flag Day | C9: يوم العلم السعودي | D9: March 11 | E9: Q1 | F9: Patriotic Celebration | G9: 300 | H9: Light
A10: 6 | B10: Ramadan Iftar | C10: إفطار رمضان | D10: Mid-March | E10: Q1 | F10: Corporate Iftar | G10: 300 | H10: Major
A11: 7 | B11: Mother's Day | C11: يوم الأم | D11: March 21 | E11: Q1 | F11: Appreciation Event | G11: 130 | H11: Medium
A12: 8 | B12: Saudi Green Initiative | C12: المبادرة الخضراء السعودية | D12: March 27 | E12: Q1 | F12: Sustainability Awareness | G12: 250 | H12: Light
A13: 9 | B13: Ehsan Philanthropy Campaign | C13: حملة إحسان | D13: March | E13: Q1 | F13: CSR/Charity | G13: 200 | H13: Light
A14: 10 | B14: Eid Al-Fitr Celebration | C14: احتفال عيد الفطر | D14: Early April | E14: Q2 | F14: Major Gala | G14: 300 | H14: Major
A15: 11 | B15: Creativity & Innovation Day | C15: يوم الإبداع والابتكار | D15: April 21 | E15: Q2 | F15: Professional Development | G15: 200 | H15: Medium
A16: 12 | B16: International Tea Day | C16: اليوم العالمي للشاي | D16: May 21 | E16: Q2 | F16: Social/Wellness | G16: 250 | H16: Light
... A45: 41 | B45: Year-End Celebration | C45: حفل نهاية العام | D45: Late December | E45: Q4 | F45: Major Gala | G45: 300 | H45: Major
A46: S1 | B46: Football Tournament | C46: بطولة كرة القدم | D46: TBD (3 weekends) | E46: Sports | F46: Sports Competition | G46: 150 | H46: Major
A47: S2 | B47: Padel Tournament | C47: بطولة البادل | D47: TBD (2 weekends) | E47: Sports | F47: Sports Competition | G47: 20 | H47: Medium
A48: S3 | B48: Walking Challenge & SERA Friday | C48: تحدي المشي + جمعة سيرا | D48: Quarterly + Annual | E48: Sports | F48: Sports/Wellness | G48: 200 | H48: Medium
A51: BUDGET SUMMARY (Linked from Financial Proposal & Sports Budget)
A52: Category | B52: # Events | C52: Total (SAR) | D52: % of Annual
A53: Q1 Events | B53: 9 | C53: ='Financial Proposal'!E595 | D53: =C53/C58
A54: Q2 Events | B54: 8 | C54: ='Financial Proposal'!E596 | D54: =C54/C59
A55: Q3 Events | B55: 8 | C55: ='Financial Proposal'!E597 | D55: =C55/C60
A56: Q4 Events | B56: 16 | C56: ='Financial Proposal'!E598 | D56: =C56/C58
A57: Sports Events | B57: 3 | C57: ='Sports Budget'!E2
A58: GRAND TOTAL (ex-VAT) | C58: ='Financial Proposal'!E605
A59: VAT (15%) | C59: =C58*0.15
A60: ★ GRAND TOTAL (inc. VAT) | C60: =C58+C59

Sheet Technical Proposal
A1: SERA 2026 — TECHNICAL PROPOSAL (EVENT SPECIFICATIONS)
A3: # | B3: Event Name | C3: Date | D3: Venue Recommendation | E3: Stage & Décor | F3: Audio-Visual Requirements | G3: Key Services & Scope
A4: 1 | B4: Annual Meeting 2026 | C4: Feb 3 | D4: 5-Star Hotel Ballroom (Ritz-Carlton / Four Seasons) | E4: Stage 8m×5m, branded backdrop, podium with SERA logo | F4: LED Wall P2.5 5m×3m, Line-array sound, 6 wireless mics, live streaming | G4: Simultaneous AR/EN translation, Prof. MC, Registration QR system, Photography (2), Videography (2), Printed materials
A5: 2 | B5: Founding Day | C5: Feb 22 | D5: SERA HQ – Internal | E5: Heritage displays, Founding Day national theme | F5: Sound for anthem + speeches | G5: Heritage displays, commemorative items, social media live coverage
A6: 3 | B6: Employee Appreciation Day | C6: Mar 2 | D6: 5-Star Hotel – Gala round-table setup | E6: Gala stage, premium décor, uplighting, award pedestals | F6: Full AV, spotlight for awards, background music system | G6: 12 crystal trophies, Live band (2.5hr), Gift boxes, Prof. MC, Full photo/video team
A7: 4 | B7: International Women's Day | C7: Mar 8 | D7: Boutique venue or hotel ladies' section | E7: Elegant feminine décor, premium floral arrangements | F7: Projector, wireless mic, ambient music | G7: Female keynote + panel (3 speakers), Photo booth, Curated gift bags, Female photographer
A8: 5 | B8: Saudi Flag Day | C8: Mar 11 | D8: SERA HQ – Lobby & outdoor | E8: Large Saudi flag (5m+), national green/white theme | F8: Portable sound for anthem + speeches | G8: Flag ceremony, Commemorative items, Social media live coverage
A9: 6 | B9: Ramadan Iftar | C9: Mid-Mar | D9: 5-Star Hotel Ramadan Tent | E9: Traditional Ramadan décor: lanterns, crescents, VIP majlis | F9: Ambient lighting, background system | G9: Premium Iftar buffet, Oud player, Ramadan gift boxes, Prayer area arrangement
A10: 7 | B10: Mother's Day | C10: Mar 21 | D10: Elegant restaurant private section | E10: Floral-themed décor, photo area | F10: Basic sound for music/announcements | G10: Flower gifts, Special mother gifts, Entertainment, Photography
A11: 8 | B11: Saudi Green Initiative | C11: Mar 27 | D11: SERA HQ – Exhibition area | E11: Green/sustainability themed booths, eco displays | F11: Presentation setup, ambient music | G11: Environmental expert, Green exhibits, Eco giveaways, Sustainability displays
A12: 9 | B12: Ehsan Philanthropy Campaign | C12: March | D12: SERA HQ – Lobby area | E12: Ehsan platform displays, donation stations | F12: Basic presentation setup | G12: Campaign awareness booth, QR donation stations, Impact stories display
A13: 10 | B13: Eid Al-Fitr Celebration | C13: Early Apr | D13: 5-Star Hotel Grand Ballroom | E13: Festive Eid gold/white, large stage, entrance arch | F13: Full production: LED wall, concert sound, lighting design | G13: Ardah troupe + live music, Eid gifts, Children's corner (optional), Prof. MC
A14: 11 | B14: Creativity & Innovation Day | C14: Apr 21 | D14: Conference Center | E14: Main stage + 10 department innovation booths | F14: Conference AV, booth displays, digital voting | G14: Keynote speaker, Innovation competition, 7 awards, Interactive voting
A15: 12 | B15: International Tea Day | C15: May 21 | D15: SERA HQ Common Areas | E15: Tea-themed décor, 3 service stations | F15: Background music | G15: Arabic/English/Asian tea stations, Gourmet pairings, Tea culture displays
... A44: 41 | B44: Year-End Celebration | C44: Late Dec | D44: 5-Star Hotel – Premium Gala | E44: Premium stage, LED lighting design, luxury tables | F44: Full gala: LED wall, concert sound, designer lighting | G44: Premium band + acts, 15 annual awards, Year-review video, Premium gifts, Prof. MC. BOOK 3 MONTHS AHEAD

Sheet Financial Proposal
A1: SERA 2026 — FINANCIAL PROPOSAL (DETAILED COST BREAKDOWN)
A2: Saudi Electricity Regulatory Authority | Currency: SAR | All Prices EXCLUDE 15% VAT | Agency Commission: 15%
A5: Q1 EVENTS
A6: EVENT 1: Annual Meeting 2026 | Date: February 3 | Attendance: 300 | 5-Star Hotel Ballroom
A7: Cost Item | B7: Unit | C7: Qty | D7: Unit Price (SAR) | E7: Total (SAR) | F7: Notes
A8: Venue Rental (5-star ballroom, full day) | B8: Full day | C8: 1 | D8: 58000 | E8: =C8*D8 | F8: Ritz-Carlton / Four Seasons / Fairmont
A9: Catering – Premium Lunch Buffet | B9: Per person | C9: 300 | D9: 270 | E9: =C9*D9 | F9: Premium hotel buffet, 10+ items, live stations
A10: Catering – 2x Coffee Breaks | B10: Per person | C10: 300 | D10: 65 | E10: =C10*D10 | F10: Morning + afternoon break, premium selection
A11: Stage & Branded Backdrop (8m x 5m) | B11: Package | C11: 1 | D11: 24000 | E11: =C11*D11 | F11: Custom SERA branded, modular stage
A12: LED Video Wall (P2.5, 5m x 3m) | B12: Rental | C12: 1 | D12: 18000 | E12: =C12*D12 | F12: With dedicated operator
A13: Professional Sound System (Line Array) | B13: Package | C13: 1 | D13: 12000 | E13: =C13*D13 | F13: Concert-grade + 6 wireless mics + monitors
A14: Simultaneous Translation (AR/EN) | B14: Package | C14: 1 | D14: 18000 | E14: =C14*D14 | F14: 2 interpreters + booth + headsets for 300
A15: Professional Photography (2 photographers) | B15: Full day | C15: 1 | D15: 8000 | E15: =C15*D15 | F15: 500+ edited high-res photos, 3-day delivery
A16: Professional Videography (2 cameras) | B16: Full day | C16: 1 | D16: 12000 | E16: =C16*D16 | F16: 5-min highlight + full event recording, 4K
A17: Registration System & Name Badges | B17: Package | C17: 1 | D17: 6500 | E17: =C17*D17 | F17: Digital QR check-in + printed badges + app
A18: Printed Materials (agenda, notepad, pen) | B18: Per person | C18: 300 | D18: 45 | E18: =C18*D18 | F18: Premium branded stationery set
A19: Professional MC (Bilingual AR/EN) | B19: Full event | C19: 1 | D19: 10000 | E19: =C19*D19 | F19: Experienced corporate MC
... A21: Welcome Lounge & VIP Hospitality | B21: Package | C21: 1 | D21: 12000 | E21: =C21*D21 | F21: VIP reception area with premium refreshments
A22: Subtotal (Before Commission) | E22: =SUM(E8:E21)
A23: Agency Commission (15%) | B23: 15% | E23: =E22*0.15 | F23: Agency management, planning & execution fee
A24: ▶ EVENT 1: Annual Meeting 2026 – TOTAL | E24: =E22+E23
A26: EVENT 2: Founding Day (يوم التأسيس) | Date: February 22 | Attendance: 300 | SERA HQ
A27: Cost Item | B27: Unit | C27: Qty | D27: Unit Price (SAR) | E27: Total (SAR) | F27: Notes
A28: Venue | B28: SERA HQ | C28: 1 | D28: 0 | E28: =C28*D28 | F28: Internal – no rental cost
A29: National Décor & Heritage Displays | B29: Package | C29: 1 | D29: 14000 | E29: =C29*D29 | F29: Founding Day theme, heritage artifacts, timeline display
A30: Sound System Rental | B30: Rental | C30: 1 | D30: 5000 | E30: =C30*D30 | F30: For national anthem + speeches + ambient
A31: Commemorative Items (badges, pins, flags) | B31: Per person | C31: 300 | D31: 42 | E31: =C31*D31 | F31: Custom SERA + Founding Day branding
A32: Light Refreshments (Traditional Saudi) | B32: Per person | C32: 300 | D32: 55 | E32: =C32*D32 | F32: Arabic coffee, dates, Saudi heritage sweets
A33: Photography | B33: 3 hours | C33: 1 | D33: 4000 | E33: =C33*D33 | F33: Event documentation
A34: Social Media Live Coverage | B34: Package | C34: 1 | D34: 4500 | E34: =C34*D34 | F34: Real-time posts + stories + reels
A35: Event Branding & Design | B35: Package | C35: 1 | D35: 14000 | E35: =C35*D35 | F35: Heritage-themed signage, displays, social media kit
A36: Subtotal (Before Commission) | E36: =SUM(E28:E35)
A37: Agency Commission (15%) | B37: 15% | E37: =E36*0.15 | F37: Agency management, planning & execution fee
A38: ▶ EVENT 2: Founding Day (يوم التأسيس) – TOTAL | E38: =E36+E37
A40: EVENT 3: Employee Appreciation Day | Date: March 2 | Attendance: 300 | 5-Star Hotel – Evening Gala
A41: Cost Item | B41: Unit | C41: Qty | D41: Unit Price (SAR) | E41: Total (SAR) | F41: Notes
A42: Venue Rental (Gala table setup) | B42: Evening | C42: 1 | D42: 52000 | E42: =C42*D42 | F42: Ballroom with round-table gala setup
A43: Catering – Gala Dinner (3-course plated) | B43: Per person | C43: 300 | D43: 330 | E43: =C43*D43 | F43: Premium plated service + welcome drinks + dessert bar
A44: Live Band Entertainment | B44: Package | C44: 1 | D44: 22000 | E44: =C44*D44 | F44: Professional band, 2.5-hour set
A45: Stage, Gala Décor & Lighting Design | B45: Package | C45: 1 | D45: 35000 | E45: =C45*D45 | F45: Premium gala theme, centerpieces, uplighting, LED features
...

Sheet Sports Budget
A1: SERA 2026 — SPORTS EVENTS BUDGET
A2: SPORTS GRAND TOTAL (inc. 15% Commission) | E2: =E30+E54+E73
A4: FOOTBALL TOURNAMENT | 10 Teams x 15 Players = 150 Players | Men Only | 3 Weekends (6 match days)
A5: Cost Item | B5: Unit | C5: Qty | D5: Unit Price (SAR) | E5: Total (SAR) | F5: Notes
A6: Football Pitch Rental (2 pitches) | B6: Per day | C6: 6 | D6: 7000 | E6: =C6*D6 | F6: 6 match days, 2 parallel pitches
A7: Team Jerseys (Numbered + SERA logo) | B7: Per set of 15 | C7: 10 | D7: 2800 | E7: =C7*D7 | F7: 10 teams x 15 jerseys, unique colors
A8: Tournament Match Balls (Official) | B8: Per ball | C8: 15 | D8: 180 | E8: =C8*D8 | F8: Official match balls + spares
A9: Training Equipment (Cones, bibs, etc.) | B9: Package | C9: 1 | D9: 2000 | E9: =C9*D9 | F9: Shared training equipment
A10: Main Referees | B10: Per match | C10: 15 | D10: 500 | E10: =C10*D10 | F10: [NOTE] Riyadh-based Saudi FA certified – no travel
A11: Assistant Referees (Linesmen) | B11: Per match | C11: 15 | D11: 300 | E11: =C11*D11 | F11: 2 per match
A12: Tournament Coordinator | B12: Per tournament | C12: 1 | D12: 8000 | E12: =C12*D12 | F12: Full tournament management + bracket
A13: First Aid / Medical Staff | B13: Per day | C13: 6 | D13: 1000 | E13: =C13*D13 | F13: On-site medical support – mandatory
A14: Champion Trophy (Large Crystal) | B14: Trophy | C14: 1 | D14: 4500 | E14: =C14*D14 | F14: Premium crystal trophy
A15: Runner-Up Trophy | B15: Trophy | C15: 1 | D15: 2500 | E15: =C15*D15
A16: Third Place Trophy | B16: Trophy | C16: 1 | D16: 2000 | E16: =C16*D16
A17: MVP Award | B17: Award | C17: 1 | D17: 600 | E17: =C17*D17
A18: Top Scorer Award (Golden Boot) | B18: Award | C18: 1 | D18: 600 | E18: =C18*D18
A19: Best Goalkeeper Award | B19: Award | C19: 1 | D19: 600 | E19: =C19*D19
A20: Best Player per Team Award | B20: Award | C20: 10 | D20: 600 | E20: =C20*D20 | F20: [NOTE] Optional – 1 per team recognition
A21: Medals (Top 3 teams) | B21: Per medal | C21: 45 | D21: 60 | E21: =C21*D21 | F21: 15 players x 3 teams
A22: Player Refreshments | B22: Per day | C22: 6 | D22: 2000 | E22: =C22*D22 | F22: Water, isotonic drinks, fruits, snacks
A23: Post-Match Light Meals | B23: Per day | C23: 6 | D23: 1200 | E23: =C23*D23 | F23: [NOTE] Optional – post-match meal for players
A24: Sports Photographer | B24: Per day | C24: 6 | D24: 2000 | E24: =C24*D24 | F24: Match + ceremony photos
A25: Digital Scoreboard Display | B25: Per day | C25: 6 | D25: 600 | E25: =C25*D25 | F25: [NOTE] Digital display if venue supports
A26: Social Media Tournament Coverage | B26: Package | C26: 1 | D26: 3000 | E26: =C26*D26 | F26: Live updates, stories, highlights
A27: Opening Ceremony | B27: Package | C27: 1 | D27: 12000 | E27: =C27*D27 | F27: Stage, national anthem, first-kick ceremony
A28: Football – Subtotal (Before Commission) | E28: =SUM(E6:E27)
A29: Agency Commission (15%) | E29: =E28*0.15
A30: ▶ FOOTBALL TOURNAMENT – TOTAL | E30: =E28+E29
A33: PADEL TOURNAMENT | 10 Teams (Doubles) = 20 Players | Men Only | 1-2 Weekends
A34: Cost Item | B34: Unit | C34: Qty | D34: Unit Price (SAR) | E34: Total (SAR) | F34: Notes
A35: Padel Court Rental | B35: Per 90-min slot | C35: 25 | D35: 480 | E35: =C35*D35 | F35: 25 matches, [NOTE] Group booking discount may apply
A36: Tournament Padel Balls | B36: Dozen | C36: 6 | D36: 200 | E36: =C36*D36 | F36: Fresh balls per round
A37: Branded Player Towels | B37: Per player | C37: 20 | D37: 50 | E37: =C37*D37 | F37: Tournament souvenir
A38: Branded Water Bottles (Reusable) | B38: Per player | C38: 20 | D38: 40 | E38: =C38*D38 | F38: Branded reusable
A39: Referees / Court Coordinators | B39: Per day | C39: 4 | D39: 700 | E39: =C39*D39 | F39: [NOTE] Riyadh-based – no travel
A40: Tournament Coordinator | B40: Package | C40: 1 | D40: 5000 | E40: =C40*D40 | F40: Bracket management + logistics
A41: Champion Trophy (Team) | B41: Trophy | C41: 1 | D41: 3000 | E41: =C41*D41
A42: Runner-Up Trophy | B42: Trophy | C42: 1 | D42: 2000 | E42: =C42*D42
A43: MVP Award | B43: Award | C43: 1 | D43: 500 | E43: =C43*D43
...

Sheet Assumptions & Notes
A1: SERA 2026 — ASSUMPTIONS, NOTES & PAYMENT TERMS
A3: KEY ASSUMPTIONS
A4: # | B4: Assumption | C4: Impact if Different | D4: Action Required
A5: 1 | B5: All events in Riyadh only – no travel costs | C5: Other cities add 15-25% for travel, accommodation, logistics | D5: Confirm all events are Riyadh-based
A6: 2 | B6: Reception events: 250-300 attendees | C6: Catering, venue, gifts scale linearly | D6: SERA to confirm headcount 2 weeks before
A7: 3 | B7: Sports: 10 teams per sport, men only | C7: More teams = longer tournament + more jerseys/venue | D7: Registration cap at 10 teams
A8: 4 | B8: All referees Riyadh-based – no travel | C8: Out-of-city refs add SAR 2K-5K travel each | D8: Use local Saudi FA/Padel Federation certified
A9: 5 | B9: SERA HQ available at no cost for internal events | C9: External venue for all = +SAR 15K-25K per awareness event | D9: SERA admin to confirm HQ availability
A10: 6 | B10: Standard gifts (SAR 50-150 range) | C10: Premium/luxury gifts (SAR 200-500) double the line item | D10: Confirm gift tier per event category
A11: 7 | B11: SERA does not own professional AV equipment | C11: Own AV = reduce SAR 8K-20K per event | D11: Audit SERA's existing AV inventory
A12: 8 | B12: Standard professional entertainment | C12: Celebrity = SAR 50K-500K+ additional per appearance | D12: Confirm entertainment tier per major event
A13: 9 | B13: Ramadan 2026 dates per expected Hijri calendar | C13: Shifting dates affect Q1/Q2 scheduling | D13: Confirm when official dates announced
A14: 10 | B14: 2026 prices with 5-10% inflation from 2025 | C14: If contracts delayed, additional adjustment needed | D14: Include price escalation clause
A15: 11 | B15: Agency commission: 15% on all events | C15: Industry range is 10-20% depending on scope | D15: Standard for full-service event management
A16: 12 | B16: VAT at 15% (ZATCA standard) | C16: Rate changes affect total | D16: Applied to all taxable services
... A20: 16 | B20: Children's Corner at Eid = optional (families may not be invited) | C20: If families attend, add SAR 12K per Eid event | D20: SERA to confirm family invitation policy
A23: PAYMENT TERMS (KSA Market Standard)
A24: # | B24: Term | C24: Condition | D24: Details
A25: 1 | B25: Advance Payment | C25: 30% upon contract signing | D25: Secures venue bookings and vendor commitments
A26: 2 | B26: Progress Payment | C26: 40% two weeks before each event | D26: Triggers final vendor confirmations and material production
A27: 3 | B27: Final Payment | C27: 30% within 14 business days post-event | D27: Upon delivery of photos, videos, and evaluation report
A28: 4 | B28: Cancellation 30+ days | C28: 100% refund of advance | D28: Full refund minus non-recoverable vendor deposits
A29: 5 | B29: Cancellation 15-30 days | C29: 50% refund | D29: Venue and vendor cancellation fees apply
A30: 6 | B30: Cancellation <15 days | C30: No refund | D30: Full charges apply – vendors already committed
A31: 7 | B31: Event Postponement | C31: Rescheduling at no extra charge | D31: Subject to venue/vendor availability within 60 days
A32: 8 | B32: Price Validity | C32: 90 days from proposal date | D32: Subject to vendor rate confirmations
A33: 9 | B33: Annual Contract Discount | C33: 5-8% for full annual commitment | D33: Negotiable based on payment terms
A36: COST OPTIMIZATION OPPORTUNITIES
A37: # | B37: Opportunity | C37: Potential Savings (SAR) | D37: Recommendation
A38: 1 | B38: Annual vendor contracts (preferred rates) | C38: 200,000 – 350,000 | D38: STRONGLY RECOMMENDED – negotiate 10-15% volume discounts
A39: 2 | B39: Maximize SERA HQ for awareness events | C39: 120,000 – 180,000 | D39: RECOMMENDED – save venue budget for major galas
A40: 3 | B40: Bundled AV equipment annual rental | C40: 50,000 – 80,000 | D40: RECOMMENDED – consistency + lower rates
A41: 4 | B41: Bundled photography/videography contract | C41: 40,000 – 65,000 | D41: RECOMMENDED – familiar with SERA brand
A42: 5 | B42: Reduce gift tier for awareness days | C42: 40,000 – 60,000 | D42: RECOMMENDED – reserve premium for celebrations
A43: 6 | B43: Off-peak weekday timing for awareness events | C43: 60,000 – 100,000 | D43: CONSIDER – may reduce attendance
A44: 7 | B44: Standard entertainment for mid-tier events | C44: 80,000 – 130,000 | D44: SELECTIVELY APPLY – keep premium for Eid, National Day, Year-End
